404 Not Found: The requested URL was not found on the server. If you entered the URL manually please check your spelling and try again.
Traceback (most recent call last):
  File "/usr/local/lib/python3.10/dist-packages/flask/app.py", line 870, in full_dispatch_request
    rv = self.dispatch_request()
  File "/usr/local/lib/python3.10/dist-packages/flask/app.py", line 844, in dispatch_request
    self.raise_routing_exception(req)
  File "/usr/local/lib/python3.10/dist-packages/flask/app.py", line 453, in raise_routing_exception
    raise request.routing_exception  # type: ignore[misc]
  File "/usr/local/lib/python3.10/dist-packages/flask/ctx.py", line 362, in match_request
    result = self.url_adapter.match(return_rule=True)  # type: ignore
  File "/usr/local/lib/python3.10/dist-packages/werkzeug/routing/map.py", line 624, in match
    raise NotFound() from None
werkzeug.exceptions.NotFound: 404 Not Found: The requested URL was not found on the server. If you entered the URL manually please check your spelling and try again.
404 Not Found: The requested URL was not found on the server. If you entered the URL manually please check your spelling and try again.
Traceback (most recent call last):
  File "/usr/local/lib/python3.10/dist-packages/flask/app.py", line 870, in full_dispatch_request
    rv = self.dispatch_request()
  File "/usr/local/lib/python3.10/dist-packages/flask/app.py", line 844, in dispatch_request
    self.raise_routing_exception(req)
  File "/usr/local/lib/python3.10/dist-packages/flask/app.py", line 453, in raise_routing_exception
    raise request.routing_exception  # type: ignore[misc]
  File "/usr/local/lib/python3.10/dist-packages/flask/ctx.py", line 362, in match_request
    result = self.url_adapter.match(return_rule=True)  # type: ignore
  File "/usr/local/lib/python3.10/dist-packages/werkzeug/routing/map.py", line 624, in match
    raise NotFound() from None
werkzeug.exceptions.NotFound: 404 Not Found: The requested URL was not found on the server. If you entered the URL manually please check your spelling and try again.
401 Unauthorized: The server could not verify that you are authorized to access the URL requested. You either supplied the wrong credentials (e.g. a bad password), or your browser doesn't understand how to supply the credentials required.
Traceback (most recent call last):
  File "/usr/local/lib/python3.10/dist-packages/flask/app.py", line 870, in full_dispatch_request
    rv = self.dispatch_request()
  File "/usr/local/lib/python3.10/dist-packages/flask/app.py", line 855, in dispatch_request
    return self.ensure_sync(self.view_functions[rule.endpoint])(**view_args)  # type: ignore[no-any-return]
  File "/usr/local/lib/python3.10/dist-packages/flask_login/utils.py", line 285, in decorated_view
    return current_app.login_manager.unauthorized()
  File "/usr/local/lib/python3.10/dist-packages/flask_login/login_manager.py", line 178, in unauthorized
    abort(401)
  File "/usr/local/lib/python3.10/dist-packages/flask/helpers.py", line 272, in abort
    current_app.aborter(code, *args, **kwargs)
  File "/usr/local/lib/python3.10/dist-packages/werkzeug/exceptions.py", line 861, in __call__
    raise self.mapping[code](*args, **kwargs)
werkzeug.exceptions.Unauthorized: 401 Unauthorized: The server could not verify that you are authorized to access the URL requested. You either supplied the wrong credentials (e.g. a bad password), or your browser doesn't understand how to supply the credentials required.
Fail put 801d093e9a4911ef9f140242ac120006/Data Bulanan Bulog Juni.xlsx: S3 operation failed; code: NoSuchBucket, message: The specified bucket does not exist, resource: /801d093e9a4911ef9f140242ac120006, request_id: 18049EABAE21BA83, host_id: dd9025bab4ad464b049177c95eb6ebf374d3b3fd1af9251148b658df7ac2e3e8, bucket_name: 801d093e9a4911ef9f140242ac120006
ES updateByQuery deleteByQuery: NotFoundError(404, 'index_not_found_exception', 'no such index [ragflow_801d07ae9a4911ef9f140242ac120006]', ragflow_801d07ae9a4911ef9f140242ac120006, index_or_alias)【Q】：{'match': {'doc_id': 'a2a49b989a4911efbd310242ac120006'}}
ES updateByQuery deleteByQuery: NotFoundError(404, 'index_not_found_exception', 'no such index [ragflow_801d07ae9a4911ef9f140242ac120006]', ragflow_801d07ae9a4911ef9f140242ac120006, index_or_alias)【Q】：{'match': {'doc_id': 'a2a49b989a4911efbd310242ac120006'}}
ES updateByQuery deleteByQuery: NotFoundError(404, 'index_not_found_exception', 'no such index [ragflow_801d07ae9a4911ef9f140242ac120006]', ragflow_801d07ae9a4911ef9f140242ac120006, index_or_alias)【Q】：{'match': {'doc_id': 'a2a49b989a4911efbd310242ac120006'}}
2024-11-04 01:13:36,807 ERROR    (23) Can't update token usage for 801d07ae9a4911ef9f140242ac120006/EMBEDDING
2024-11-04 01:13:38,145 ERROR    (23) Can't update token usage for 801d07ae9a4911ef9f140242ac120006/EMBEDDING
2024-11-04 01:13:58,506 ERROR    (23) Can't update token usage for 801d07ae9a4911ef9f140242ac120006/EMBEDDING
2024-11-04 01:14:07,008 ERROR    (23) Can't update token usage for 801d07ae9a4911ef9f140242ac120006/EMBEDDING
Can't update token usage for 801d07ae9a4911ef9f140242ac120006/EMBEDDING
